<mujoco model="WF_GOAT">
    <compiler angle="radian" coordinate="local" meshdir="meshes/" autolimits="true"/>
    
    <option timestep="0.002" gravity="0 0 -9.81"/>

    <visual>
        <headlight diffuse="0.6 0.6 0.6" ambient="0.3 0.3 0.3" specular="0 0 0"/>
        <rgba haze="0.15 0.25 0.35 1"/>
        <global azimuth="120" elevation="-20"/>
    </visual>

    <asset>
        <texture  name="groundplane" type="2d" builtin="checker" mark="edge" rgb1="0.2 0.3 0.4" rgb2="0.1 0.2 0.3" markrgb="0.8 0.8 0.8" width="512" height="512"/>
        <material name="groundplane" texture="groundplane" texuniform="true" texrepeat="5 5" reflectance="0.2"/>
    </asset>

    <worldbody>
        <light directional="true" diffuse=".8 .8 .8" specular=".2 .2 .2" pos="0 0 5" dir="0 0 -1"/>
        <geom name="floor" type="plane" size="0 0 1" material="groundplane"/>
    </worldbody>

    <asset>
        <mesh name="base_Link" file="base_Link_simple.stl"/>
        <mesh name="hip_L_Link" file="hip_L_Link.stl"/>
        <mesh name="hip_R_Link" file="hip_R_Link.stl"/>
        <mesh name="thigh_L_Link" file="thigh_L_Link.stl"/>
        <mesh name="thigh_R_Link" file="thigh_R_Link.stl"/>
        <mesh name="calf_L_Link" file="calf_L_Link.stl"/>
        <mesh name="calf_R_Link" file="calf_R_Link.stl"/>
        <mesh name="wheel_L_Link" file="wheel_L_Link.stl"/>
        <mesh name="wheel_R_Link" file="wheel_R_Link.stl"/>
        
        <material name="orange" rgba="1.0 0.423 0.039 1.0"/>
        <material name="black" rgba="0.792 0.819 0.933 1.0"/>
        <material name="white" rgba="1.0 1.0 1.0 1.0"/>
    </asset>

    <default>
        <joint damping="0.0" frictionloss="0.0"/>
        <geom contype="1" conaffinity="1" friction="0.65 0.1 0.1"/>
        <motor ctrllimited="true"/>
    </default>

    <worldbody>
        <body name="base_Link" pos="0 0 1.0">
            <!-- Floating base (active). For a FIXED base, comment out the freejoint
                 below: a world-attached body with no free joint is rigidly fixed at
                 this body's pos/quat. Doing so changes nq 15->8 and nv 14->8, so also
                 switch to the fixed-base <keyframe> alternative further down. -->
            <!-- <freejoint name="root"/> -->
            <site name="imu_site" pos="0 0 0" size="0.01" type="sphere" rgba="1 0 0 1"/>
            
            <inertial pos="-0.009521 0.000016 -0.072346" mass="2.818" fullinertia="0.02028445 0.023476973 0.021206204 -0.000005647 0.006404633 0.000000541"/>
            <geom type="mesh" mesh="base_Link" material="black" pos="-0.1235 0 0.0155" contype="0" conaffinity="0" group="1"/>
            <geom type="box" size="0.107 0.100 0.095" pos="-0.02 0 -0.015" group="3"/>

            <body name="hip_L_Link" pos="0.038386 0.094233 -0.152597">
                <joint name="hip_L_Joint" type="hinge" axis="-1 0 0" range="-1.7453 1.0123" damping="0.0" frictionloss="0.0" armature="0.001"/>
                <inertial pos="-0.048092 -0.038296 -0.000162" mass="0.32" fullinertia="0.0001437 0.0002157 0.0001977 -0.0000128 -0.00000153 -0.000000447"/>
                <geom type="mesh" mesh="hip_L_Link" material="black" contype="0" conaffinity="0" group="1"/>
                <geom type="cylinder" size="0.042 0.0675" pos="-0.0535 0 0" euler="1.57 0 0" group="3"/>

                <body name="thigh_L_Link" pos="-0.054 -0.017 0">
                    <joint name="thigh_L_Joint" type="hinge" axis="0 1 0" range="-0.3840 2.0071" damping="0.0" frictionloss="0.0" armature="0.001"/>
                    <inertial pos="-0.002292 0.044134 -0.032074" mass="0.429" fullinertia="0.002141 0.002065 0.000345 -0.000025 -0.000067 -0.000348"/>
                    <geom type="mesh" mesh="thigh_L_Link" material="white" contype="0" conaffinity="0" group="1"/>
                    <geom type="box" size="0.045 0.025 0.0725" pos="-0.011 0.016 -0.116" group="3"/>

                    <body name="calf_L_Link" pos="0 0.018 -0.205">
                        <joint name="knee_L_Joint" type="hinge" axis="0 -1 0" range="-0.523599 2.3387" damping="0.0" frictionloss="0.0" armature="0.001"/>
                        <inertial pos="0.001922 0.000564 -0.169664" mass="0.287" fullinertia="0.001163 0.001199 0.000092 0.0000005 -0.000035 0.0000013"/>
                        <geom type="mesh" mesh="calf_L_Link" material="black" contype="0" conaffinity="0" group="1"/>
                        <geom type="cylinder" size="0.0325 0.1165" pos="0 0 -0.116" group="3"/>

                        <body name="wheel_L_Link" pos="0 0.016555 -0.200">
                            <joint name="wheel_L_Joint" type="hinge" axis="0 1 0" damping="0.0" frictionloss="0.0" armature="0.001"/>
                            <inertial pos="0 0.007264 -0.000002" mass="0.212" fullinertia="0.000338 0.000647 0.000338 -0.000000001 -0.000000008 0.000000001"/>
                            <geom type="mesh" mesh="wheel_L_Link" material="orange" contype="0" conaffinity="0" group="1"/>
                            <geom name="wheel_L_collision" type="cylinder" size="0.07275 0.016" pos="0 0.007 0" euler="1.5707 0 0" group="3"/>
                        </body>
                    </body>
                </body>
            </body>

            <body name="hip_R_Link" pos="0.038386 -0.094233 -0.152597">
                <joint name="hip_R_Joint" type="hinge" axis="-1 0 0" range="-1.0123 1.7453" damping="0.0" frictionloss="0.0" armature="0.001"/>
                <inertial pos="-0.048092 0.038296 -0.000162" mass="0.32" fullinertia="0.000143 0.000215 0.000197 0.000012 -0.000001 0.0000004"/>
                <geom type="mesh" mesh="hip_R_Link" material="black" contype="0" conaffinity="0" group="1"/>
                <geom type="cylinder" size="0.042 0.0675" pos="-0.0535 0 0" euler="1.57 0 0" group="3"/>

                <body name="thigh_R_Link" pos="-0.054 0.017 0">
                    <joint name="thigh_R_Joint" type="hinge" axis="0 -1 0" range="-2.0071 0.3840" damping="0.0" frictionloss="0.0" armature="0.001"/>
                    <inertial pos="-0.002292 -0.044134 -0.032074" mass="0.429" fullinertia="0.002141 0.002065 0.000345 0.000025 -0.000067 0.000348"/>
                    <geom type="mesh" mesh="thigh_R_Link" material="white" contype="0" conaffinity="0" group="1"/>
                    <geom type="box" size="0.045 0.025 0.0725" pos="-0.011 -0.016 -0.116" group="3"/>

                    <body name="calf_R_Link" pos="0 -0.018 -0.205">
                        <joint name="knee_R_Joint" type="hinge" axis="0 1 0" range="-2.3387 0.523599" damping="0.0" frictionloss="0.0" armature="0.001"/>
                        <inertial pos="0.001922 -0.000564 -0.169664" mass="0.287" fullinertia="0.001163 0.001199 0.000092 -0.0000005 -0.000035 -0.0000013"/>
                        <geom type="mesh" mesh="calf_R_Link" material="black" contype="0" conaffinity="0" group="1"/>
                        <geom type="cylinder" size="0.0325 0.1165" pos="0 0 -0.116" group="3"/>

                        <body name="wheel_R_Link" pos="0 -0.016555 -0.200">
                            <joint name="wheel_R_Joint" type="hinge" axis="0 -1 0" damping="0.0" frictionloss="0.0" armature="0.001"/>
                            <inertial pos="0 -0.007264 -0.000002" mass="0.212" fullinertia="0.000338 0.000647 0.000338 0.000000001 -0.000000008 -0.000000001"/>
                            <geom type="mesh" mesh="wheel_R_Link" material="orange" contype="0" conaffinity="0" group="1"/>
                            <geom name="wheel_R_collision" type="cylinder" size="0.07275 0.016" pos="0 -0.007 0" euler="1.5707 0 0" group="3"/>
                        </body>
                    </body>
                </body>
            </body>
        </body>
    </worldbody>

    <!-- Wheel-ground friction controlled explicitly via contact pairs.
         friction = [slide1, slide2, torsion, roll1, roll2]; condim=3 (sliding only).
         Other collision geoms (legs/base) still use default dynamic contacts (max rule). -->
    <contact>
        <pair name="floor_wheel_L" geom1="floor" geom2="wheel_L_collision" condim="3" friction="1.0 1.0 0.001 0.0001 0.0001"/>
        <pair name="floor_wheel_R" geom1="floor" geom2="wheel_R_collision" condim="3" friction="1.0 1.0 0.001 0.0001 0.0001"/>
    </contact>

    <!-- Torque-based actuator -->
    <actuator>
        <motor name="hip_L_motor" joint="hip_L_Joint" ctrllimited="true" ctrlrange="-4.5 4.5"/>
        <motor name="thigh_L_motor" joint="thigh_L_Joint" ctrllimited="true" ctrlrange="-4.5 4.5"/>
        <motor name="knee_L_motor" joint="knee_L_Joint" ctrllimited="true" ctrlrange="-9.0 9.0"/>
        <motor name="wheel_L_motor" joint="wheel_L_Joint" ctrllimited="true" ctrlrange="-2.5 2.5"/>
        <motor name="hip_R_motor" joint="hip_R_Joint" ctrllimited="true" ctrlrange="-4.5 4.5"/>
        <motor name="thigh_R_motor" joint="thigh_R_Joint" ctrllimited="true" ctrlrange="-4.5 4.5"/>
        <motor name="knee_R_motor" joint="knee_R_Joint" ctrllimited="true" ctrlrange="-9.0 9.0"/>
        <motor name="wheel_R_motor" joint="wheel_R_Joint" ctrllimited="true" ctrlrange="-2.5 2.5"/>
    </actuator>

    <!-- Position-based actuator -->
    <!-- <actuator>
        <position name="hip_L_motor"   joint="hip_L_Joint"   kp="3.0" kv="0.5"   ctrllimited="true" ctrlrange="-1.7453 1.0123"   forcelimited="true" forcerange="-4.5 4.5"/>
        <position name="thigh_L_motor" joint="thigh_L_Joint" kp="3.0" kv="0.5"   ctrllimited="true" ctrlrange="-0.3840 2.0071"   forcelimited="true" forcerange="-4.5 4.5"/>
        <position name="knee_L_motor"  joint="knee_L_Joint"  kp="3.0" kv="0.5"   ctrllimited="true" ctrlrange="-0.523599 2.3387" forcelimited="true" forcerange="-9.0 9.0"/>
        <velocity name="wheel_L_motor" joint="wheel_L_Joint" kv="0.002"          ctrllimited="true" ctrlrange="-15.0 15.0"       forcelimited="true" forcerange="-2.5 2.5"/>
        <position name="hip_R_motor"   joint="hip_R_Joint"   kp="3.0" kv="0.5"   ctrllimited="true" ctrlrange="-1.0123 1.7453"   forcelimited="true" forcerange="-4.5 4.5"/>
        <position name="thigh_R_motor" joint="thigh_R_Joint" kp="3.0" kv="0.5"   ctrllimited="true" ctrlrange="-2.0071 0.3840"   forcelimited="true" forcerange="-4.5 4.5"/>
        <position name="knee_R_motor"  joint="knee_R_Joint"  kp="3.0" kv="0.5"   ctrllimited="true" ctrlrange="-2.3387 0.523599" forcelimited="true" forcerange="-9.0 9.0"/>
        <velocity name="wheel_R_motor" joint="wheel_R_Joint" kv="0.002"          ctrllimited="true" ctrlrange="-15.0 15.0"       forcelimited="true" forcerange="-2.5 2.5"/>
    </actuator> -->


    <!-- Floating-base keyframe (active; matches the freejoint above)
        qpos (nq=15): base[x y z]  base_quat[w x y z]  | hipL thighL kneeL wheelL  hipR thighR kneeR wheelR
        qvel (nv=14): base[vx vy vz wx wy wz]          | 8 joint velocities
        ctrl (nu=8) : 8 actuators -->
    <!-- <keyframe>
        <key name="hanging"
             qpos="0.0 0.0 1.0   1.0 0.0 0.0 0.0   0.0 0.0 0.0 0.0   0.0 0.0 0.0 0.0"
             qvel="0.0 0.0 0.0 0.0 0.0 0.0   0.0 0.0 0.0 0.0   0.0 0.0 0.0 0.0"
             ctrl="0.0 0.0 0.0 0.0 0.0 0.0 0.0 0.0"/>
    </keyframe> -->

    <!-- Fixed-base keyframe alternative. Use this (and comment out the floating-base
         keyframe above) when the freejoint is removed: nq=8, nv=8.
         qpos order (8): hipL thighL kneeL wheelL  hipR thighR kneeR wheelR
         qvel order (8): 8 joint velocities ; ctrl (8): 8 actuators -->
    <keyframe>
        <key name="home"
             qpos="0.0 0.0 0.0 0.0   0.0 0.0 0.0 0.0"
             qvel="0.0 0.0 0.0 0.0   0.0 0.0 0.0 0.0"
             ctrl="0.0 0.0 0.0 0.0 0.0 0.0 0.0 0.0"/>
    </keyframe>
   
    <sensor>
        <accelerometer name="imu_acc" site="imu_site"/>
        <gyro name="imu_gyro" site="imu_site"/>
        <magnetometer name="imu_mag" site="imu_site"/>
    </sensor>

</mujoco>